<?xml version="1.0" ?>
   <robot name="mbot">
   
       <link name="base_link">
           <visual>
             <origin xyz=" 0 0 0" rpy="0 0 0" /> <!-- xyz:机器人模型在xyz轴上偏移的长度(单位m)  rpy:绕xyz三轴旋转的角度(弧度);  -->
               <geometry>
                   <cylinder length="0.16" radius="0.20"/>
               </geometry>
              <material name="yellow">
                  <color rgba="1 0.4 0 1"/>   <!-- rgb a:0-1颜色透明度  -->
              </material>
          </visual>
      </link>
  
      <joint name="left_wheel_joint" type="continuous">  <!-- joint的origin用来描述joint连接的子link与母link之间的坐标关系  -->
          <origin xyz="0 0.19 -0.05" rpy="0 0 0"/><!-- xyz:机器人模型在xyz轴上偏移的长度(单位m)(相对于praent_link)  rpy:绕xyz三轴旋转的角度(弧度);  -->
          <parent link="base_link"/>
          <child link="left_wheel_link"/>
          <axis xyz="0 1 0"/>  <!-- 关节可以绕着y轴旋转  -->
      </joint>
  
      <link name="left_wheel_link">
          <visual>
              <origin xyz="0 0 0" rpy="1.5707 0 0" />
              <geometry>
                  <cylinder radius="0.06" length = "0.025"/>
              </geometry>
              <material name="white">
                  <color rgba="1 1 1 0.9"/>
              </material>
          </visual>
      </link>
  
      <joint name="right_wheel_joint" type="continuous">
          <origin xyz="0 -0.19 -0.05" rpy="0 0 0"/>
          <parent link="base_link"/>
          <child link="right_wheel_link"/>
          <axis xyz="0 1 0"/>
      </joint>
  
      <link name="right_wheel_link">
          <visual>
              <origin xyz="0 0 0" rpy="1.5707 0 0" />
              <geometry>
                  <cylinder radius="0.06" length = "0.025"/>
              </geometry>
              <material name="white">
                  <color rgba="1 1 1 0.9"/>
              </material>
          </visual>
      </link>
  
      <joint name="front_caster_joint" type="continuous">
          <origin xyz="0.18 0 -0.095" rpy="0 0 0"/>
          <parent link="base_link"/>
          <child link="front_caster_link"/>
          <axis xyz="0 1 0"/>
      </joint>
  
      <link name="front_caster_link">
          <visual>
              <origin xyz="0 0 0" rpy="0 0 0"/>
              <geometry>
                  <sphere radius="0.015" />
              </geometry>
              <material name="black">
                  <color rgba="0 0 0 0.95"/>
              </material>
          </visual>
      </link>
  
      <joint name="back_caster_joint" type="continuous">
          <origin xyz="-0.18 0 -0.095" rpy="0 0 0"/>
          <parent link="base_link"/>
          <child link="back_caster_link"/>
          <axis xyz="0 1 0"/>
      </joint>
  
      <link name="back_caster_link">
          <visual>
              <origin xyz="0 0 0" rpy="0 0 0"/>
              <geometry>
                  <sphere radius="0.015" />
              </geometry>
              <material name="black">
                  <color rgba="0 0 0 0.95"/>
              </material>
          </visual>
      </link>
  
      <link name="kinect_link">
          <visual>
              <origin xyz="0 0 0" rpy="0 0 1.5708"/>
              <geometry>
                  <mesh filename="package://mbot_description/meshes/kinect.dae" />
              </geometry>
          </visual>
      </link>
 
     <joint name="kinect_joint" type="fixed">
         <origin xyz="0.15 0 0.11" rpy="0 0 0"/>
         <parent link="base_link"/>
         <child link="kinect_link"/>
     </joint>

     <link name="camera_link">
        <visual>
            <origin xyz=" 0 0 0 " rpy="0 0 0" />
            <geometry>
                <box size="0.03 0.04 0.04" />
            </geometry>
            <material name="black">
                <color rgba="0 0 0 0.95"/>
            </material>
        </visual>
    </link>

    <joint name="camera_joint" type="fixed">
        <origin xyz="-0.17 0 0.10" rpy="0 0 0"/>
        <parent link="base_link"/>
        <child link="camera_link"/>
    </joint>

    <link name="laser_link">
		<visual>
			<origin xyz=" 0 0 0 " rpy="0 0 0" />
			<geometry>
				<cylinder length="0.05" radius="0.05"/>
			</geometry>
			<material name="black"/>
		</visual>
    </link>

    <joint name="laser_joint" type="fixed">
        <origin xyz="0 0 0.105" rpy="0 0 0"/>
        <parent link="base_link"/>
        <child link="laser_link"/>
    </joint>
   
 
 </robot>
